<?xml version="1.0" encoding="utf-8"?>
<!-- This URDF was automatically created by SolidWorks to URDF Exporter! Originally created by Stephen Brawner (brawner@gmail.com)
     Commit Version: 1.5.1-0-g916b5db  Build Version: 1.5.7152.31018
     For more information, please see http://wiki.ros.org/sw_urdf_exporter -->
<robot
  name="cheetos">
  <link
    name="body">
    <inertial>
      <origin
        xyz="-0.131665588733977 0.00265396784555805 0.166170951769268"
        rpy="0 0 0" />
      <mass
        value="2.3" />
      <inertia
        ixx="0.0159559051940881"
        ixy="-7.18469676817871E-07"
        ixz="0.00189725904228338"
        iyy="0.0429827313478047"
        iyz="-5.74968905705857E-08"
        izz="0.0546231565087513" />
    </inertial>
    <visual>
      <origin
        xyz="0 0 0"
        rpy="0 0 0" />
      <geometry>
        <mesh
          filename="package://cheetos_description/meshes/body.STL" />
      </geometry>
      <material
        name="">
        <color
          rgba="1 1 1 1" />
      </material>
    </visual>
    <collision>
      <origin
        xyz="0 0 0"
        rpy="0 0 0" />
      <geometry>
        <mesh
          filename="package://cheetos_description/meshes/body.STL" />
      </geometry>
    </collision>
  </link>
<link name="dummy"/>

  <joint name="base_joint" type="fixed">
    <parent link="dummy"/>
    <child link="body" />
  </joint>
  <link
    name="LeftSuspension">
    <inertial>
      <origin
        xyz="0.0012247 -4.7186E-05 -0.0072077"
        rpy="0 0 0" />
      <mass
        value="0.55433" />
      <inertia
        ixx="8.6239E-05"
        ixy="-1.5645E-06"
        ixz="2.9641E-08"
        iyy="0.00012163"
        iyz="-1.6485E-07"
        izz="0.00015669" />
    </inertial>
    <visual>
      <origin
        xyz="0 0 0"
        rpy="0 0 0" />
      <geometry>
        <mesh
          filename="package://cheetos_description/meshes/LeftSuspension.STL" />
      </geometry>
      <material
        name="">
        <color
          rgba="0.89804 0.91765 0.92941 1" />
      </material>
    </visual>
    <collision>
      <origin
        xyz="0 0 0"
        rpy="0 0 0" />
      <geometry>
        <mesh
          filename="package://cheetos_description/meshes/LeftSuspension.STL" />
      </geometry>
    </collision>
  </link>
  <joint
    name="LeftSuspension"
    type="prismatic">
    <origin
      xyz="0.0219999999999989 0.110000000000005 0.09029"
      rpy="0 0 0" />
    <parent
      link="body" />
    <child
      link="LeftSuspension" />
    <axis
      xyz="0 0 1" />
    <limit
      lower="-0.02"
      upper="0"
      effort="100"
      velocity="0.01" />
  </joint>
  <link
    name="LeftMotor">
    <inertial>
      <origin
        xyz="0.0012247 -4.7186E-05 -0.0072077"
        rpy="0 0 0" />
      <mass
        value="0.55433" />
      <inertia
        ixx="8.6239E-05"
        ixy="-1.5645E-06"
        ixz="2.9641E-08"
        iyy="0.00012163"
        iyz="-1.6485E-07"
        izz="0.00015669" />
    </inertial>
    <visual>
      <origin
        xyz="0 0 0"
        rpy="0 0 0" />
      <geometry>
        <mesh
          filename="package://cheetos_description/meshes/LeftMotor.STL" />
      </geometry>
      <material
        name="">
        <color
          rgba="0.89804 0.91765 0.92941 1" />
      </material>
    </visual>
    <collision>
      <origin
        xyz="0 0 0"
        rpy="0 0 0" />
      <geometry>
        <mesh
          filename="package://cheetos_description/meshes/LeftMotor.STL" />
      </geometry>
    </collision>
  </link>
  <joint
    name="LeftMotor"
    type="fixed">
    <origin
      xyz="0 0 -0.0245"
      rpy="0 0 0" />
    <parent
      link="LeftSuspension" />
    <child
      link="LeftMotor" />
    <axis
      xyz="0 0 0" />
  </joint>
  <link
    name="LeftWheel">
    <inertial>
      <origin
        xyz="-8.3267E-17 -2.9698E-15 3.4694E-18"
        rpy="0 0 0" />
      <mass
        value="0.39667" />
      <inertia
        ixx="0.00059162"
        ixy="8.7084E-22"
        ixz="-2.3396E-36"
        iyy="0.0011235"
        iyz="3.3722E-36"
        izz="0.00059162" />
    </inertial>
    <visual>
      <origin
        xyz="0 0 0"
        rpy="1.5708 0 0" />
      <geometry>
               <cylinder length="0.04" radius="0.07"/>
      </geometry>
      <material
        name="">
        <color
          rgba="1 1 1 1" />
      </material>
    </visual>
    <collision>
      <origin
        xyz="0 0 0"
        rpy="1.5708 0 0" />
      <geometry>
        <cylinder length="0.04" radius="0.07"/>
      </geometry>
    </collision>
  </link>
  <joint
    name="LeftWheel"
    type="continuous">
    <origin
      xyz="0.013 0.02775 -0.011787"
      rpy="0 0 0" />
    <parent
      link="LeftMotor" />
    <child
      link="LeftWheel" />
    <axis
      xyz="0 1 0" />
    <limit
      effort="3.1"
      velocity="7" />
  </joint>
  <link
    name="RightSuspension">
    <inertial>
      <origin
        xyz="0.0012247 4.7186E-05 -0.0072492"
        rpy="0 0 0" />
      <mass
        value="0.55433" />
      <inertia
        ixx="8.6239E-05"
        ixy="1.5645E-06"
        ixz="-2.9641E-08"
        iyy="0.00012163"
        iyz="-1.6485E-07"
        izz="0.00015669" />
    </inertial>
    <visual>
      <origin
        xyz="0 0 0"
        rpy="0 0 0" />
      <geometry>
        <mesh
          filename="package://cheetos_description/meshes/RightSuspension.STL" />
      </geometry>
      <material
        name="">
        <color
          rgba="0.89804 0.91765 0.92941 1" />
      </material>
    </visual>
    <collision>
      <origin
        xyz="0 0 0"
        rpy="0 0 0" />
      <geometry>
        <mesh
          filename="package://cheetos_description/meshes/RightSuspension.STL" />
      </geometry>
    </collision>
  </link>
  <joint
    name="RightSuspension"
    type="prismatic">
    <origin
      xyz="0.022 -0.11 0.09029"
      rpy="0 0 0" />
    <parent
      link="body" />
    <child
      link="RightSuspension" />
    <axis
      xyz="0 0 1" />
    <limit
      lower="-0.02"
      upper="0"
      effort="100"
      velocity="0.01" />
  </joint>
  <link
    name="RightMotor">
    <inertial>
      <origin
        xyz="0.0012247 4.7186E-05 -0.0072492"
        rpy="0 0 0" />
      <mass
        value="0.55433" />
      <inertia
        ixx="8.6239E-05"
        ixy="1.5645E-06"
        ixz="-2.9641E-08"
        iyy="0.00012163"
        iyz="-1.6485E-07"
        izz="0.00015669" />
    </inertial>
    <visual>
      <origin
        xyz="0 0 0"
        rpy="0 0 0" />
      <geometry>
        <mesh
          filename="package://cheetos_description/meshes/RightMotor.STL" />
      </geometry>
      <material
        name="">
        <color
          rgba="0.89804 0.91765 0.92941 1" />
      </material>
    </visual>
    <collision>
      <origin
        xyz="0 0 0"
        rpy="0 0 0" />
      <geometry>
        <mesh
          filename="package://cheetos_description/meshes/RightMotor.STL" />
      </geometry>
    </collision>
  </link>
  <joint
    name="RightMotor"
    type="fixed">
    <origin
      xyz="0 0 -0.0245"
      rpy="0 0 0" />
    <parent
      link="RightSuspension" />
    <child
      link="RightMotor" />
    <axis
      xyz="0 0 0" />
  </joint>
  <link
    name="RightWheel">
    <inertial>
      <origin
        xyz="-1.3878E-16 -2.8311E-15 3.4694E-18"
        rpy="0 0 0" />
      <mass
        value="0.39667" />
      <inertia
        ixx="0.00059162"
        ixy="-1.8658E-18"
        ixz="-8.9798E-20"
        iyy="0.0011235"
        iyz="-4.1551E-21"
        izz="0.00059162" />
    </inertial>
    <visual>
      <origin
        xyz="0 0 0"
        rpy="1.5708 0 0" />
      <geometry>
               <cylinder length="0.04" radius="0.07"/>
      </geometry>
      <material
        name="">
        <color
          rgba="1 1 1 1" />
      </material>
    </visual>
    <collision>
      <origin
        xyz="0 0 0"
        rpy="1.5708 0 0" />
      <geometry>
        <cylinder length="0.04" radius="0.07"/>
      </geometry>
    </collision>
  </link>
  <joint
    name="RightWheel"
    type="continuous">
    <origin
      xyz="0.0129999999999996 -0.0277499999999998 -0.0117849999999997"
      rpy="0 0 0" />
    <parent
      link="RightMotor" />
    <child
      link="RightWheel" />
    <axis
      xyz="0 1 0" />
    <limit
      effort="3.1"
      velocity="7" />
  </joint>
  <link
    name="RearSuspension">
    <inertial>
      <origin
        xyz="-0.010041 6.4226E-18 -0.02367"
        rpy="0 0 0" />
      <mass
        value="0.34774" />
      <inertia
        ixx="0.00056998"
        ixy="5.7272E-20"
        ixz="-6.9341E-05"
        iyy="0.0001687"
        iyz="-1.1998E-19"
        izz="0.00048148" />
    </inertial>
    <visual>
      <origin
        xyz="0 0 0"
        rpy="0 0 0" />
      <geometry>
        <mesh
          filename="package://cheetos_description/meshes/RearSuspension.STL" />
      </geometry>
      <material
        name="">
        <color
          rgba="0.89804 0.91765 0.92941 1" />
      </material>
    </visual>
    <collision>
      <origin
        xyz="0 0 0"
        rpy="0 0 0" />
      <geometry>
        <mesh
          filename="package://cheetos_description/meshes/RearSuspension.STL" />
      </geometry>
    </collision>
  </link>
  <joint
    name="RearSuspension"
    type="prismatic">
    <origin
      xyz="-0.27 0 0.08"
      rpy="0 0 0" />
    <parent
      link="body" />
    <child
      link="RearSuspension" />
    <axis
      xyz="0 0 1" />
    <limit
      lower="-0.04"
      upper="0"
      effort="100"
      velocity="0.01" />
  </joint>
  <link
    name="CasterJoint">
    <inertial>
      <origin
        xyz="-0.010041 6.4226E-18 -0.02367"
        rpy="0 0 0" />
      <mass
        value="0.34774" />
      <inertia
        ixx="0.00056998"
        ixy="5.7272E-20"
        ixz="-6.9341E-05"
        iyy="0.0001687"
        iyz="-1.1998E-19"
        izz="0.00048148" />
    </inertial>
    <visual>
      <origin
        xyz="0 0 0"
        rpy="0 0 0" />
      <geometry>
        <mesh
          filename="package://cheetos_description/meshes/CasterJoint.STL" />
      </geometry>
      <material
        name="">
        <color
          rgba="0.89804 0.91765 0.92941 1" />
      </material>
    </visual>
    <collision>
      <origin
        xyz="0 0 0"
        rpy="0 0 0" />
      <geometry>
        <mesh
          filename="package://cheetos_description/meshes/CasterJoint.STL" />
      </geometry>
    </collision>
  </link>
  <joint
    name="CasterJoint"
    type="prismatic">
    <origin
      xyz="0 0 -0.0075"
      rpy="0 0 0" />
    <parent
      link="RearSuspension" />
    <child
      link="CasterJoint" />
    <axis
      xyz="0 0 1" />
    <limit
      lower="-0.04"
      upper="0"
      effort="1000"
      velocity="1000" />
  </joint>
  <link
    name="Sphere">
    <inertial>
      <origin
        xyz="0 -2.4931E-20 6.9389E-18"
        rpy="0 0 0" />
      <mass
        value="0.358335" />
      <inertia
        ixx="0.00045942"
        ixy="1.0361E-38"
        ixz="-2.8818E-40"
        iyy="0.00046321"
        iyz="0"
        izz="0.00045942" />
    </inertial>
    <visual>
      <origin
        xyz="0 0 0"
        rpy="0 0 0" />
      <geometry>
        <sphere radius="0.04"/>
      </geometry>
      <material
        name="">
        <color
          rgba="0.89804 0.91765 0.92941 1" />
      </material>
    </visual>
    <collision>
      <origin
        xyz="0 0 0"
        rpy="0 0 0" />
      <geometry>
          <sphere radius="0.04"/>
      </geometry>
    </collision>
  </link>
  <joint
    name="Sphere"
    type="continuous">
    <origin
      xyz="-0.02372975512794 0 -0.0485"
      rpy="0 0 0" />
    <parent
      link="CasterJoint" />
    <child
      link="Sphere" />
    <axis
      xyz="0 1 0" />
  </joint>
  <link
    name="Lidar">
    <inertial>
      <origin
        xyz="-0.0106584194573059 0.00149536433385656 -0.0184322088779122"
        rpy="0 0 0" />
      <mass
        value="0.0730845804596596" />
      <inertia
        ixx="1.95855192972885E-05"
        ixy="-1.78553755169841E-07"
        ixz="4.28488283975004E-07"
        iyy="2.41203647877997E-05"
        iyz="-2.38491004481269E-09"
        izz="4.1418451413048E-05" />
    </inertial>
    <visual>
      <origin
        xyz="0 0 0"
        rpy="0 0 0" />
      <geometry>
        <mesh
          filename="package://cheetos_description/meshes/Ridar.STL" />
      </geometry>
      <material
        name="">
        <color
          rgba="0.792156862745098 0.819607843137255 0.933333333333333 1" />
      </material>
    </visual>
    <collision>
      <origin
        xyz="0 0 0"
        rpy="0 0 0" />
      <geometry>
        <mesh
          filename="package://cheetos_description/meshes/Ridar.STL" />
      </geometry>
    </collision>
  </link>
  <joint
    name="Lidar"
    type="fixed">
    <origin
      xyz="-0.1392 -0.0060445 0.35617"
      rpy="0 0 0" />
    <parent
      link="body" />
    <child
      link="Lidar" />
    <axis
      xyz="0 0 0" />
  </joint>
  <link
    name="imu_link">
    <inertial>
      <origin
        xyz="-5.80684691974323E-05 -0.000929499747983537 0.000334718190330485"
        rpy="0 0 0" />
      <mass
        value="0.00100170070350826" />
      <inertia
        ixx="1.69531813597037E-08"
        ixy="-1.30603108853935E-11"
        ixz="-3.36807508028114E-18"
        iyy="3.03936181819941E-08"
        iyz="-6.24614435388015E-14"
        izz="4.63286907007238E-08" />
    </inertial>
    <visual>
      <origin
        xyz="0 0 0"
        rpy="0 0 0" />
      <geometry>
        <mesh
          filename="package://cheetos_description/meshes/imu_link.STL" />
      </geometry>
      <material
        name="">
        <color
          rgba="0.752941176470588 0.752941176470588 0.752941176470588 1" />
      </material>
    </visual>
    <collision>
      <origin
        xyz="0 0 0"
        rpy="0 0 0" />
      <geometry>
        <mesh
          filename="package://cheetos_description/meshes/imu_link.STL" />
      </geometry>
    </collision>
  </link>
  <joint
    name="IMU"
    type="fixed">
    <origin
      xyz="-0.27194 -0.15957 0.313"
      rpy="0 0 0" />
    <parent
      link="body" />
    <child
      link="imu_link" />
    <axis
      xyz="0 0 0" />
  </joint>
  <link
    name="CamUp">
    <inertial>
      <origin
        xyz="-0.0240608797344701 -0.000831103636230159 -0.0086820542686866"
        rpy="0 0 0" />
      <mass
        value="0.0814567527016656" />
      <inertia
        ixx="2.93819154283946E-05"
        ixy="5.3332956002618E-07"
        ixz="-2.59288616701654E-07"
        iyy="1.39017043298223E-05"
        iyz="-9.705250623736E-09"
        izz="3.66776098846521E-05" />
    </inertial>
    <visual>
      <origin
        xyz="0 0 0"
        rpy="0 0 0" />
      <geometry>
        <mesh
          filename="package://cheetos_description/meshes/CamUp.STL" />
      </geometry>
      <material
        name="">
        <color
          rgba="0.752941176470588 0.752941176470588 0.752941176470588 1" />
      </material>
    </visual>
    <collision>
      <origin
        xyz="0 0 0"
        rpy="0 0 0" />
      <geometry>
        <mesh
          filename="package://cheetos_description/meshes/CamUp.STL" />
      </geometry>
    </collision>
  </link>
  <joint
    name="CamUp"
    type="fixed">
    <origin
      xyz="0.056625 0.0021836 0.25151"
      rpy="0 0 0" />
    <parent
      link="body" />
    <child
      link="CamUp" />
    <axis
      xyz="0 0 0" />
  </joint>
  <link
    name="CamLow">
    <inertial>
      <origin
        xyz="-0.0240608775291059 -0.000831104433010251 -0.00868205335954153"
        rpy="0 0 0" />
      <mass
        value="0.0814567470324938" />
      <inertia
        ixx="2.9381914414346E-05"
        ixy="5.33327967811365E-07"
        ixz="-2.592877551454E-07"
        iyy="1.39017011370152E-05"
        iyz="-9.70568132352121E-09"
        izz="3.66776060324368E-05" />
    </inertial>
    <visual>
      <origin
        xyz="0 0 0"
        rpy="0 0 0" />
      <geometry>
        <mesh
          filename="package://cheetos_description/meshes/CamLow.STL" />
      </geometry>
      <material
        name="">
        <color
          rgba="0.752941176470588 0.752941176470588 0.752941176470588 1" />
      </material>
    </visual>
    <collision>
      <origin
        xyz="0 0 0"
        rpy="0 0 0" />
      <geometry>
        <mesh
          filename="package://cheetos_description/meshes/CamLow.STL" />
      </geometry>
    </collision>
  </link>
  <joint
    name="CamLow"
    type="fixed">
    <origin
      xyz="0.056625 0.0021836 0.19651"
      rpy="0 0 0" />
    <parent
      link="body" />
    <child
      link="CamLow" />
    <axis
      xyz="0 0 0" />
  </joint>
  <link
    name="CamRear">
    <inertial>
      <origin
        xyz="-0.0240609788733489 0.000828264941201923 -0.00868205846297625"
        rpy="0 0 0" />
      <mass
        value="0.0814567724559934" />
      <inertia
        ixx="2.93817636646625E-05"
        ixy="-5.35534285119911E-07"
        ixz="-2.59340623789365E-07"
        iyy="1.39018545991374E-05"
        iyz="8.17789182622398E-09"
        izz="3.66776079026737E-05" />
    </inertial>
    <visual>
      <origin
        xyz="0 0 0"
        rpy="0 0 0" />
      <geometry>
        <mesh
          filename="package://cheetos_description/meshes/CamRear.STL" />
      </geometry>
      <material
        name="">
        <color
          rgba="0.752941176470588 0.752941176470588 0.752941176470588 1" />
      </material>
    </visual>
    <collision>
      <origin
        xyz="0 0 0"
        rpy="0 0 0" />
      <geometry>
        <mesh
          filename="package://cheetos_description/meshes/CamRear.STL" />
      </geometry>
    </collision>
  </link>
  <joint
    name="CamRear"
    type="fixed">
    <origin
      xyz="-0.344 0.0021836 0.19651"
      rpy="0 0 -3.1416" />
    <parent
      link="body" />
    <child
      link="CamRear" />
    <axis
      xyz="0 0 0" />
  </joint>
  <link
    name="CamRear_Up">
    <inertial>
      <origin
        xyz="0.0240609810197435 -0.000828265854513086 -0.00868205937212058"
        rpy="0 0 0" />
      <mass
        value="0.081456778125166" />
      <inertia
        ixx="2.93817648508048E-05"
        ixy="-5.35532606603709E-07"
        ixz="2.59341454118007E-07"
        iyy="1.39018575661722E-05"
        iyz="-8.17836672748321E-09"
        izz="3.66776117012104E-05" />
    </inertial>
    <visual>
      <origin
        xyz="0 0 0"
        rpy="0 0 0" />
      <geometry>
        <mesh
          filename="package://cheetos_description/meshes/CamRear_Up.STL" />
      </geometry>
      <material
        name="">
        <color
          rgba="0.752941176470588 0.752941176470588 0.752941176470588 1" />
      </material>
    </visual>
    <collision>
      <origin
        xyz="0 0 0"
        rpy="0 0 0" />
      <geometry>
        <mesh
          filename="package://cheetos_description/meshes/CamRear_Up.STL" />
      </geometry>
    </collision>
  </link>
  <joint
    name="CamRear_Up"
    type="fixed">
    <origin
      xyz="-0.344 0.0021836 0.25151"
      rpy="0 0 0" />
    <parent
      link="body" />
    <child
      link="CamRear_Up" />
    <axis
      xyz="0 0 0" />
  </joint>
<transmission name="front_wheel_left_transmission">
    <type>transmission_interface/SimpleTransmission</type>
    <joint name="LeftWheel">
      <hardwareInterface>hardware_interface/EffortJointInterface</hardwareInterface>
    </joint>
    <actuator name="Front_Left_Wheel_Motor">
      <hardwareInterface>hardware_interface/EffortJointInterface</hardwareInterface>
      <mechanicalReduction>1</mechanicalReduction>
    </actuator>
  </transmission>
  <transmission name="front_wheel_right_transmission">
    <type>transmission_interface/SimpleTransmission</type>
    <joint name="RightWheel">
      <hardwareInterface>hardware_interface/EffortJointInterface</hardwareInterface>
    </joint>
    <actuator name="Front_Right_Wheel_Motor">
      <hardwareInterface>hardware_interface/EffortJointInterface</hardwareInterface>
      <mechanicalReduction>1</mechanicalReduction>
    </actuator>
  </transmission>
   <transmission name="front_suspension_right_transmission">
    <type>transmission_interface/SimpleTransmission</type>
    <joint name="RightSuspension">
      <hardwareInterface>hardware_interface/EffortJointInterface</hardwareInterface>
    </joint>
    <actuator name="front_Right_suspension_Motor">
      <hardwareInterface>hardware_interface/EffortJointInterface</hardwareInterface>
      <mechanicalReduction>1</mechanicalReduction>
    </actuator>
  </transmission>
  <transmission name="front_suspension_left_transmission">
    <type>transmission_interface/SimpleTransmission</type>
    <joint name="LeftSuspension">
      <hardwareInterface>hardware_interface/EffortJointInterface</hardwareInterface>
    </joint>
    <actuator name="front_Left_suspension_Motor">
      <hardwareInterface>hardware_interface/EffortJointInterface</hardwareInterface>
      <mechanicalReduction>1</mechanicalReduction>
    </actuator>
  </transmission>
  <transmission name="rear_suspension_transmission">
    <type>transmission_interface/SimpleTransmission</type>
    <joint name="RearSuspension">
      <hardwareInterface>hardware_interface/EffortJointInterface</hardwareInterface>
    </joint>
    <actuator name="rear_suspension_Motor">
      <hardwareInterface>hardware_interface/EffortJointInterface</hardwareInterface>
      <mechanicalReduction>1</mechanicalReduction>
    </actuator>
  </transmission>
<gazebo>
  <plugin name="gazebo_ros_control" filename="libgazebo_ros_control.so">
    <robotNamespace>/cheetos</robotNamespace>
    <robotSimType>gazebo_ros_control/DefaultRobotHWSim</robotSimType>
  </plugin>
</gazebo>

<gazebo reference="body">
  <material>Gazebo/Orange</material>
</gazebo>

<gazebo reference="LeftSuspension">
  <material>Gazebo/White</material>
</gazebo>

<gazebo reference="LeftMotor">
  <material>Gazebo/Black</material>
</gazebo>

<gazebo reference="LeftWheel">
  <mu1>1.0</mu1>
  <mu2>1.0</mu2>
  <material>Gazebo/Grey</material>
</gazebo>

<gazebo reference="RightSuspension">
  <material>Gazebo/White</material>
</gazebo>

<gazebo reference="RightMotor">
  <material>Gazebo/Black</material>
</gazebo>

<gazebo reference="RightWheel">
  <mu1>1.0</mu1>
  <mu2>1.0</mu2>
  <material>Gazebo/Grey</material>
</gazebo>

<gazebo reference="Sphere">
  <mu1>0.5</mu1>
  <mu2>0.5</mu2>
  <material>Gazebo/Grey</material>
</gazebo>

<gazebo reference="body">
  <mu1>0.0</mu1>
  <mu2>0.0</mu2>
</gazebo>

<gazebo reference="imu_link">
  <material>Gazebo/SkyBlue</material>
</gazebo>

<gazebo reference="CamUp">
  <material>Gazebo/Grey</material>
  <sensor type="depth" name="realsense_R200">
    <always_on>true</always_on>
    <visualize>false</visualize>
    <camera>
        <pose>0 0 0 0 0 0</pose>
        <horizontal_fov>1.3439</horizontal_fov>
        <image>
            <width>1920</width>
            <height>1080</height>
            <format>R8G8B8</format>
        </image>
        <depth_camera></depth_camera>
        <clip>
            <near>0.03</near>
            <far>100</far>
        </clip>
    </camera>
    <plugin name="camera_controller" filename="libgazebo_ros_openni_kinect.so">
      <baseline>0.2</baseline>
      <alwaysOn>true</alwaysOn>
      <updateRate>30.0</updateRate>
      <cameraName>upper_camera</cameraName>
      <frameName>upper_camera_link</frameName>
      <imageTopicName>rgb/image_raw</imageTopicName>
      <depthImageTopicName>depth/image_raw</depthImageTopicName>
      <pointCloudTopicName>depth/points</pointCloudTopicName>
      <cameraInfoTopicName>rgb/camera_info</cameraInfoTopicName>
      <depthImageCameraInfoTopicName>depth/camera_info</depthImageCameraInfoTopicName>
      <pointCloudCutoff>0.4</pointCloudCutoff>
          <hackBaseline>0.07</hackBaseline>
          <distortionK1>0.0</distortionK1>
          <distortionK2>0.0</distortionK2>
          <distortionK3>0.0</distortionK3>
          <distortionT1>0.0</distortionT1>
          <distortionT2>0.0</distortionT2>
      <CxPrime>0.0</CxPrime>
      <Cx>0.0</Cx>
      <Cy>0.0</Cy>
      <focalLength>0</focalLength>
      <hackBaseline>0</hackBaseline>
    </plugin>
  </sensor>
</gazebo>

<gazebo reference="CamLow">
  <material>Gazebo/Grey</material>
  <sensor type="depth" name="realsense_R200">
    <always_on>true</always_on>
    <visualize>false</visualize>
    <camera>
        <pose>0 0 0 0 1 0</pose>
        <horizontal_fov>1.3439</horizontal_fov>
        <image>
            <width>1920</width>
            <height>1080</height>
            <format>R8G8B8</format>
        </image>
        <depth_camera></depth_camera>
        <clip>
            <near>0.03</near>
            <far>100</far>
        </clip>
    </camera>
    <plugin name="camera_controller" filename="libgazebo_ros_openni_kinect.so">
      <baseline>0.2</baseline>
      <alwaysOn>true</alwaysOn>
      <updateRate>30.0</updateRate>
      <cameraName>lower_camera</cameraName>
      <frameName>lower_camera_link</frameName>
      <imageTopicName>rgb/image_raw</imageTopicName>
      <depthImageTopicName>depth/image_raw</depthImageTopicName>
      <pointCloudTopicName>depth/points</pointCloudTopicName>
      <cameraInfoTopicName>rgb/camera_info</cameraInfoTopicName>
      <depthImageCameraInfoTopicName>depth/camera_info</depthImageCameraInfoTopicName>
      <pointCloudCutoff>0.4</pointCloudCutoff>
          <hackBaseline>0.07</hackBaseline>
          <distortionK1>0.0</distortionK1>
          <distortionK2>0.0</distortionK2>
          <distortionK3>0.0</distortionK3>
          <distortionT1>0.0</distortionT1>
          <distortionT2>0.0</distortionT2>
      <CxPrime>0.0</CxPrime>
      <Cx>0.0</Cx>
      <Cy>0.0</Cy>
      <focalLength>0</focalLength>
      <hackBaseline>0</hackBaseline>
    </plugin>
  </sensor>
</gazebo>

<gazebo reference="CamRear">
  <material>Gazebo/Grey</material>
  <sensor type="depth" name="realsense_R200">
    <always_on>true</always_on>
    <visualize>false</visualize>
    <camera>
        <pose>0 0 0 0 1 0</pose>
        <horizontal_fov>1.3439</horizontal_fov>
        <image>
            <width>1920</width>
            <height>1080</height>
            <format>R8G8B8</format>
        </image>
        <depth_camera></depth_camera>
        <clip>
            <near>0.03</near>
            <far>100</far>
        </clip>
    </camera>
    <plugin name="camera_controller" filename="libgazebo_ros_openni_kinect.so">
      <baseline>0.2</baseline>
      <alwaysOn>true</alwaysOn>
      <updateRate>30.0</updateRate>
      <cameraName>rear_camera</cameraName>
      <frameName>rear_camera_link</frameName>
      <imageTopicName>rgb/image_raw</imageTopicName>
      <depthImageTopicName>depth/image_raw</depthImageTopicName>
      <pointCloudTopicName>depth/points</pointCloudTopicName>
      <cameraInfoTopicName>rgb/camera_info</cameraInfoTopicName>
      <depthImageCameraInfoTopicName>depth/camera_info</depthImageCameraInfoTopicName>
      <pointCloudCutoff>0.4</pointCloudCutoff>
          <hackBaseline>0.07</hackBaseline>
          <distortionK1>0.0</distortionK1>
          <distortionK2>0.0</distortionK2>
          <distortionK3>0.0</distortionK3>
          <distortionT1>0.0</distortionT1>
          <distortionT2>0.0</distortionT2>
      <CxPrime>0.0</CxPrime>
      <Cx>0.0</Cx>
      <Cy>0.0</Cy>
      <focalLength>0</focalLength>
      <hackBaseline>0</hackBaseline>
    </plugin>
  </sensor>
</gazebo>

<gazebo reference="CamRear_Up">
  <material>Gazebo/Grey</material>
  <sensor type="depth" name="realsense_R200">
    <always_on>true</always_on>
    <visualize>false</visualize>
    <camera>
        <pose>0 0 0 0 0 3.1416</pose>
        <horizontal_fov>1.3439</horizontal_fov>
        <image>
            <width>1920</width>
            <height>1080</height>
            <format>R8G8B8</format>
        </image>
        <depth_camera></depth_camera>
        <clip>
            <near>0.03</near>
            <far>100</far>
        </clip>
    </camera>
    <plugin name="camera_controller" filename="libgazebo_ros_openni_kinect.so">
      <baseline>0.2</baseline>
      <alwaysOn>true</alwaysOn>
      <updateRate>30.0</updateRate>
      <cameraName>rear_up_camera</cameraName>
      <frameName>rear_up_camera_link</frameName>
      <imageTopicName>rgb/image_raw</imageTopicName>
      <depthImageTopicName>depth/image_raw</depthImageTopicName>
      <pointCloudTopicName>depth/points</pointCloudTopicName>
      <cameraInfoTopicName>rgb/camera_info</cameraInfoTopicName>
      <depthImageCameraInfoTopicName>depth/camera_info</depthImageCameraInfoTopicName>
      <pointCloudCutoff>0.4</pointCloudCutoff>
          <hackBaseline>0.07</hackBaseline>
          <distortionK1>0.0</distortionK1>
          <distortionK2>0.0</distortionK2>
          <distortionK3>0.0</distortionK3>
          <distortionT1>0.0</distortionT1>
          <distortionT2>0.0</distortionT2>
      <CxPrime>0.0</CxPrime>
      <Cx>0.0</Cx>
      <Cy>0.0</Cy>
      <focalLength>0</focalLength>
      <hackBaseline>0</hackBaseline>
    </plugin>
  </sensor>
</gazebo>

<gazebo reference="Lidar">
  <material>Gazebo/FlatBlack</material>
  <sensor type="ray" name="lds_lfcd_sensor">
    <pose>0 0 0 0 0 0</pose>
    <visualize>false</visualize>
    <update_rate>5</update_rate>
    <ray>
      <scan>
        <horizontal>
          <samples>360</samples>
          <resolution>1</resolution>
          <min_angle>0.0</min_angle>
          <max_angle>6.28319</max_angle>
        </horizontal>
      </scan>
      <range>
        <min>0.120</min>
        <max>3.5</max>
        <resolution>0.015</resolution>
      </range>
      <noise>
        <type>gaussian</type>
        <mean>0.0</mean>
        <stddev>0.01</stddev>
      </noise>
    </ray>
    <plugin name="gazebo_ros_lds_lfcd_controller" filename="libgazebo_ros_laser.so">
      <topicName>scan</topicName>
      <frameName>Lidar</frameName>
    </plugin>
  </sensor>
</gazebo>

<gazebo reference="imu_link">
    <sensor type="imu" name="imu">
      <always_on>true</always_on>
      <visualize>true</visualize>
    </sensor>
  </gazebo>

  <gazebo>
    <plugin name="imu_plugin" filename="libgazebo_ros_imu.so">
      <alwaysOn>true</alwaysOn>
      <bodyName>imu_link</bodyName>
      <frameName>imu_link</frameName>
      <topicName>imu_test</topicName>
      <serviceName>imu_service</serviceName>
      <gaussianNoise>0.01</gaussianNoise>
      <updateRate>200</updateRate>
      <imu>
        <noise>
          <type>gaussian</type>
          <rate>
            <mean>0.0</mean>
            <stddev>2e-4</stddev>
            <bias_mean>0.0000075</bias_mean>
            <bias_stddev>0.0000008</bias_stddev>
          </rate>
          <accel>
            <mean>0.0</mean>
            <stddev>1.7e-2</stddev>
            <bias_mean>0.1</bias_mean>
            <bias_stddev>0.001</bias_stddev>
          </accel>
        </noise>
      </imu>
    </plugin>
  </gazebo>
</robot>